I'm sorry, but an uncaught exception occurred.

While running game code:
  File "game/script.rpy", line 62, in script call
    call cafe_floor_0 from _call_cafe_floor_0
  File "game/cafe_floor_0.rpy", line 179, in script
    text "WE'LL BE BACK, RIGHT AFTER THESE MESSAGES"
Exception: Sayer 'text' is not defined.

-- Full Traceback ------------------------------------------------------------

Full traceback:
  File "game/script.rpy", line 62, in script call
    call cafe_floor_0 from _call_cafe_floor_0
  File "game/cafe_floor_0.rpy", line 179, in script
    text "WE'LL BE BACK, RIGHT AFTER THESE MESSAGES"
  File "C:\Games\Renpy SDK\renpy\ast.py", line 2586, in execute
    Say.execute(self)
  File "C:\Games\Renpy SDK\renpy\ast.py", line 583, in execute
    who = eval_who(self.who, self.who_fast)
  File "C:\Games\Renpy SDK\renpy\ast.py", line 472, in eval_who
    raise Exception("Sayer '%s' is not defined." % who)
Exception: Sayer 'text' is not defined.

Windows-10-10.0.26100 AMD64
Ren'Py 8.3.7.25031702
Cafe of The Dead 1.1
Sat May  3 08:01:54 2025
